<!DOCTYPE html>
<html>
  <head>
    <meta name="pypi:repository-version" content="1.3">
    <title>Links for upy-error</title>
  </head>
  <body>
    <h1>Links for upy-error</h1>
<a href="https://files.pythonhosted.org/packages/52/3a/9fca8d8fd262fe576956a3c8024f5b4ea102ce63eb31f75fea5fa7f78954/upy-error-0.0.1.tar.gz#sha256=609dfc46bfd410adbdcdfd5966633bfb8b9bc2b012df549f94ba75f9fce78fde" data-requires-python="&gt;=3.6" >upy-error-0.0.1.tar.gz</a><br />
<a href="https://files.pythonhosted.org/packages/e2/04/00d40500da9470131aeff569716c3be3d5a2f8c0b5a8c5eea6b7332d7fde/upy_error-0.0.1-py2.py3-none-any.whl#sha256=8ce1c4d6b83e16167bf6c803053054cc264b8994f21d6fca37d16ef9c3d48df5" data-requires-python="&gt;=3.6" data-dist-info-metadata="sha256=c2871a9b69e07ad1027d8f480ea0214f856a67abba931f9d5dda67ad74f7a549" data-core-metadata="sha256=c2871a9b69e07ad1027d8f480ea0214f856a67abba931f9d5dda67ad74f7a549">upy_error-0.0.1-py2.py3-none-any.whl</a><br />
<a href="https://files.pythonhosted.org/packages/32/af/0c26dbe990fde40cfa6f32d1725d51a410eeebfa3c02236cfe83f55e2e2f/upy-error-0.0.2.tar.gz#sha256=1443e61ba8ec8c610ad761de20b3ea1604927fe876fdbb096afe043e72c7f383" data-requires-python="&gt;=3.6" >upy-error-0.0.2.tar.gz</a><br />
<a href="https://files.pythonhosted.org/packages/ab/c4/6abdc541f1478543f7aa05298ec0e75825b6e5272e87f7a75230f2913b1b/upy_error-0.0.2-py2.py3-none-any.whl#sha256=42ce128f084f6f6a02f53a19fc86ff8b2fc9b61f379f7343b16e7235d65916c2" data-requires-python="&gt;=3.6" data-dist-info-metadata="sha256=77973deed0cb9fa6bd28d7d490513697dee1e4cd4642dfa51e5ef808df20a41e" data-core-metadata="sha256=77973deed0cb9fa6bd28d7d490513697dee1e4cd4642dfa51e5ef808df20a41e">upy_error-0.0.2-py2.py3-none-any.whl</a><br />
<a href="https://files.pythonhosted.org/packages/19/34/cd281a63a9213bc32994f953fe2b40109687c5cdcce767e43571ab06a35c/upy-error-0.0.3.tar.gz#sha256=fffb5593ed88978487cf45209f189cb12a78bfab66c7f4ba123f101aeaba3f16" data-requires-python="&gt;=3.6" >upy-error-0.0.3.tar.gz</a><br />
<a href="https://files.pythonhosted.org/packages/41/db/396164e11c395dc19ef3490ff71ab1fd6fbca767ef35a59da9914ef5f307/upy_error-0.0.3-py2.py3-none-any.whl#sha256=545b0e84bffb220aab8caaa7eff6c2a400a7ed9b430d7b55b3d0b47c753f8307" data-requires-python="&gt;=3.6" data-dist-info-metadata="sha256=8bfc0332717f341d35d10d1cf8176badb179fef26b1d9d56ba49ededa77b2c99" data-core-metadata="sha256=8bfc0332717f341d35d10d1cf8176badb179fef26b1d9d56ba49ededa77b2c99">upy_error-0.0.3-py2.py3-none-any.whl</a><br />
</body>
</html>
<!--SERIAL 18114936-->